Workbook

Sheet パラメータ
A1: クレジット経済 前提パラメータ(青字セルを変更して全体をチューニング)
A3: v0:基準収入レート(月・Lv1・1隻=鉄1kg/秒相当、通貨/秒) | B3: =B11*B12 | C3: レート × 鉄基準価格 ≒ 2,762/秒。全収入・価格がVND桁で表示される
A4: r:天体ごとの収入成長係数 | B4: 1.32 | C4: 開放順に v = v0 × r^No。50体で約80万倍
A5: α:フロンティア係数 | B5: 2.5 | C5: 総収入 ≒ α × 最前線天体の収入レート(既開放天体+強化分の近似)
A6: s:アンロックへの支出比率 | B6: 0.5 | C6: 収入のうち天体購入に回る割合(残りは強化・研究)
A7: E:有効採掘時間(秒/日) | B7: 30000 | C7: 約8.3h/日=オフライン2h×4回+オンライン。オフラインLv上げで増加
A8: 速度モデル:全船統一速度S(km/分)。「速度カーブ」シートでバンド別に定義 | C8: 移動時間 = 実距離 ÷ S(線形式・例外なし)。Sは航行研究で成長
A9: ブースト倍率(アイテム/広告・一時加速) | B9: 2 | C9: 例:全船速度×2を10分間。倍率・持続は要検討
A10: ブースト持続(分) | B10: 10 | C10: 要検討
A11: USD/VND レート(基準日 2026-07-11) | B11: 26300 | C11: ゲーム内通貨「NOVA」はVND相当額に固定(基準日レートで換算し、以後の為替変動は追わない)
A12: 鉄鉱石 基準価格(USD/kg・基準日) | B12: 0.105 | C12: $105.14/t(鉄鉱石62% CFR中国)
A13: 凡例:青字=入力値(変更可)/黒=数式/黄色=重要前提。数値はすべて叩き台であり、プレイテストで調整する。
A14: 設計方針:天体ごとの「収入レート」を主軸にバランスを取り、資源の内訳(単価×採取量)は資源マスタで後決めする。
A15: ペース目標:B5小惑星帯=1週目 / B6木星圏=2週目 / B10到達=42日 / 最終セドナ=90日(天体マスタの目標日列で調整)。

Sheet 資源マスタ
A1: 資源マスタ ― VND基準・全面市況連動+金型金属追加版(基準日:2026-07-10/11、1USD=26,300VND)
A3: 資源 | B3: 連動区分 | C3: 実勢価格(USD/kg) | D3: ゲーム内単価(NOVA/kg) | E3: 連動する市況指標 | F3: 備考(★金型=プレス金型材との関係)
A4: 鉄 | B4: ★日次 | C4: 0.105 | D4: =C4*パラメータ!$B$11 | E4: 鉄鉱石62% CFR中国指数 | F4: $105.14/t。基準資源。★金型:SS400・S45C等の母材
A5: 石炭 | B5: ★日次 | C5: 0.13 | D5: =C5*パラメータ!$B$11 | E5: ICE Newcastle石炭先物 | F5: $129.75/t。地球限定第2資源(生物由来)
A6: メタン | B6: ★日次 | C6: 0.155 | D6: =C6*パラメータ!$B$11 | E6: 天然ガス Henry Hub | F6: $2.95/MMBtu
A7: メタン氷 | B7: ★日次 | C7: 0.155 | D7: =C7*パラメータ!$B$11 | E7: 天然ガス Henry Hub | F7: メタンと同一指標
A8: 炭化水素 | B8: ★日次 | C8: 0.525 | D8: =C8*パラメータ!$B$11 | E8: WTI原油先物 | F8: $71.97/bbl。タイタン限定
A9: 木材 | B9: ★日次 | C9: 0.55 | D9: =C9*パラメータ!$B$11 | E9: CME材木先物 | F9: $622.5/千bf。地球限定
A10: 鉛 | B10: ★日次 | C10: 2 | D10: =C10*パラメータ!$B$11 | E10: LME鉛 | F10: 約$2,000/t
A11: クロム | B11: ◆週次 | C11: 2.8 | D11: =C11*パラメータ!$B$11 | E11: フェロクロム(Cr分・週次指標) | F11: 概算・要確認。★金型:SKD11の13%Cr・DC53の8%Cr、硬質クロムめっき
A12: アルミニウム | B12: ★日次 | C12: 3.15 | D12: =C12*パラメータ!$B$11 | E12: LMEアルミニウム | F12: 約$3,150/t。月の斜長石に豊富(実在)
A13: 亜鉛 | B13: ★日次 | C13: 3.2 | D13: =C13*パラメータ!$B$11 | E13: LME亜鉛 | F13: 約$3,200/t。★金型:亜鉛合金(ZAS)試作型
A14: 銅 | B14: ★日次 | C14: 12.8 | D14: =C14*パラメータ!$B$11 | E14: LME銅 | F14: 約$12,800/t・史上高値圏。★金型:放電加工電極・端子プレス材
A15: ニッケル | B15: ★日次 | C15: 16.4 | D15: =C15*パラメータ!$B$11 | E15: LMEニッケル | F15: $16,400/t
... A33: チタン | B33: 固定 | C33: 9 | D33: =C33*パラメータ!$B$11 | E33: ―(四半期見直し) | F33: ★金型ではないが構造材の定番。収入資源
A34: ヘリウム | B34: 固定 | C34: 60 | D34: =C34*パラメータ!$B$11 | E34: ―
A35: ヘリウム3 | B35: 固定 | C35: ― | D35: 100000000000 | E35: ― | F35: 外縁バンドの収入アンカー(天王星・海王星が現実の採取構想の本命)
A36: 希少物質 | B36: 固定 | C36: ― | D36: 500000000000 | E36: ― | F36: ゲーム用設定・最上位(架空)
A38: 【連動範囲】日次19+週次4=計23系統が市況連動、固定10、計33資源。★金型印は「マーケット(相場モニター)」機能の金属図鑑でプレス金型材との関係を解説する対象。
A39: 【金型金属の配置】タングステン・モリブデン=親鉄元素→M型小惑星(ルテティア等・推定)。クロム=月・ベスタ(クロマイト・実在根拠)。バナジウム=分化小惑星(推定)。
A40: 【教育ネタ】タングステンは2025年初比+550%の歴史的高騰(中国輸出規制)=超硬工具コストに直撃する実例。図鑑・市況パネルの「今日の一言」で扱う。
A41: 【週次指標の注意】Cr/Mo/V/W詳細/U はFastmarkets・AsianMetal・SMM等の購読系。商用利用はライセンス契約必須。社内ダッシュボード用途なら購読1契約で兼用可。
A42: 【換算】NOVA単価 = 当日USD/kg × 26,300。日次±10%・基準日比±50%クランプ。

Sheet 天体マスタ
A1: 天体マスタ(50天体)距離・目標日=青字入力、収入レート・価格・片道時間=数式
A3: No | B3: バンド | C3: 天体名 | D3: 区分 | E3: 距離目安(km) | F3: 目標開放日 | G3: 収入レートv(cr/秒) | H3: Δt(日) | I3: アンロック価格(cr) | J3: 片道時間(分・開放時点) | K3: 主資源 | L3: 備考
A4: 0 | B4: B1 | C4: 月 | D4: 衛星 | E4: 380000 | F4: 0 | G4: =パラメータ!$B$3*パラメータ!$B$4^A4 | H4: 0 | I4: 0 | J4: =E4/INDEX(速度カーブ!$D$4:$D$13,MATCH(B4,速度カーブ!$A$4:$A$13,0)) | K4: 鉄・チタン・アルミニウム・He3(推定)・ウラン(KREEP・推定) | L4: チュートリアルで無償開放
A5: 1 | B5: B2 | C5: エロス | D5: 小惑星 | E5: 8000000 | F5: 0.2 | G5: =パラメータ!$B$3*パラメータ!$B$4^A5 | H5: =F5-F4 | I5: =ROUND(パラメータ!$B$5*G4*H5*パラメータ!$B$7*パラメータ!$B$6,-2) | J5: =E5/INDEX(速度カーブ!$D$4:$D$13,MATCH(B5,速度カーブ!$A$4:$A$13,0)) | K5: 鉄・ニッケル
A6: 2 | B6: B2 | C6: イトカワ | D6: 小惑星 | E6: 12000000 | F6: 0.5 | G6: =パラメータ!$B$3*パラメータ!$B$4^A6 | H6: =F6-F5 | I6: =ROUND(パラメータ!$B$5*G5*H6*パラメータ!$B$7*パラメータ!$B$6,-2) | J6: =E6/INDEX(速度カーブ!$D$4:$D$13,MATCH(B6,速度カーブ!$A$4:$A$13,0)) | K6: 鉄・ニッケル
A7: 3 | B7: B2 | C7: リュウグウ | D7: 小惑星 | E7: 18000000 | F7: 1 | G7: =パラメータ!$B$3*パラメータ!$B$4^A7 | H7: =F7-F6 | I7: =ROUND(パラメータ!$B$5*G6*H7*パラメータ!$B$7*パラメータ!$B$6,-2) | J7: =E7/INDEX(速度カーブ!$D$4:$D$13,MATCH(B7,速度カーブ!$A$4:$A$13,0)) | K7: 炭素質(水・有機物)
A8: 4 | B8: B2 | C8: ベンヌ | D8: 小惑星 | E8: 25000000 | F8: 1.5 | G8: =パラメータ!$B$3*パラメータ!$B$4^A8 | H8: =F8-F7 | I8: =ROUND(パラメータ!$B$5*G7*H8*パラメータ!$B$7*パラメータ!$B$6,-2) | J8: =E8/INDEX(速度カーブ!$D$4:$D$13,MATCH(B8,速度カーブ!$A$4:$A$13,0)) | K8: 炭素質(水・有機物)
A9: 5 | B9: B3 | C9: 金星 | D9: 惑星 | E9: 41000000 | F9: 2 | G9: =パラメータ!$B$3*パラメータ!$B$4^A9 | H9: =F9-F8 | I9: =ROUND(パラメータ!$B$5*G8*H9*パラメータ!$B$7*パラメータ!$B$6,-2) | J9: =E9/INDEX(速度カーブ!$D$4:$D$13,MATCH(B9,速度カーブ!$A$4:$A$13,0)) | K9: 大気成分(ゲーム用設定) | L9: 着陸不可・大気採取
A10: 6 | B10: B3 | C10: 水星 | D10: 惑星 | E10: 77000000 | F10: 2.5 | G10: =パラメータ!$B$3*パラメータ!$B$4^A10 | H10: =F10-F9 | I10: =ROUND(パラメータ!$B$5*G9*H10*パラメータ!$B$7*パラメータ!$B$6,-2) | J10: =E10/INDEX(速度カーブ!$D$4:$D$13,MATCH(B10,速度カーブ!$A$4:$A$13,0)) | K10: 鉄・ニッケル・硫黄(実在:高濃度)
A11: 7 | B11: B4 | C11: 火星 | D11: 惑星 | E11: 78000000 | F11: 3 | G11: =パラメータ!$B$3*パラメータ!$B$4^A11 | H11: =F11-F10 | I11: =ROUND(パラメータ!$B$5*G10*H11*パラメータ!$B$7*パラメータ!$B$6,-2) | J11: =E11/INDEX(速度カーブ!$D$4:$D$13,MATCH(B11,速度カーブ!$A$4:$A$13,0)) | K11: 鉄・水氷
A12: 8 | B12: B4 | C12: フォボス | D12: 衛星 | E12: 78100000 | F12: 3.5 | G12: =パラメータ!$B$3*パラメータ!$B$4^A12 | H12: =F12-F11 | I12: =ROUND(パラメータ!$B$5*G11*H12*パラメータ!$B$7*パラメータ!$B$6,-2) | J12: =E12/INDEX(速度カーブ!$D$4:$D$13,MATCH(B12,速度カーブ!$A$4:$A$13,0)) | K12: 鉄・炭素質
A13: 9 | B13: B4 | C13: ダイモス | D13: 衛星 | E13: 78200000 | F13: 4 | G13: =パラメータ!$B$3*パラメータ!$B$4^A13 | H13: =F13-F12 | I13: =ROUND(パラメータ!$B$5*G12*H13*パラメータ!$B$7*パラメータ!$B$6,-2) | J13: =E13/INDEX(速度カーブ!$D$4:$D$13,MATCH(B13,速度カーブ!$A$4:$A$13,0)) | K13: 鉄・ニッケル・クロム(クロマイト・実在根拠)
A14: 10 | B14: B5 | C14: ベスタ | D14: 小惑星 | E14: 260000000 | F14: 5 | G14: =パラメータ!$B$3*パラメータ!$B$4^A14 | H14: =F14-F13 | I14: =ROUND(パラメータ!$B$5*G13*H14*パラメータ!$B$7*パラメータ!$B$6,-2) | J14: =E14/INDEX(速度カーブ!$D$4:$D$13,MATCH(B14,速度カーブ!$A$4:$A$13,0)) | K14: 鉄・ニッケル・銅(推定)
A15: 11 | B15: B5 | C15: ケレス | D15: 準惑星 | E15: 290000000 | F15: 5.8 | G15: =パラメータ!$B$3*パラメータ!$B$4^A15 | H15: =F15-F14 | I15: =ROUND(パラメータ!$B$5*G14*H15*パラメータ!$B$7*パラメータ!$B$6,-2) | J15: =E15/INDEX(速度カーブ!$D$4:$D$13,MATCH(B15,速度カーブ!$A$4:$A$13,0)) | K15: 水氷・鉄
A16: 12 | B16: B5 | C16: パラス | D16: 小惑星 | E16: 310000000 | F16: 6.6 | G16: =パラメータ!$B$3*パラメータ!$B$4^A16 | H16: =F16-F15 | I16: =ROUND(パラメータ!$B$5*G15*H16*パラメータ!$B$7*パラメータ!$B$6,-2) | J16: =E16/INDEX(速度カーブ!$D$4:$D$13,MATCH(B16,速度カーブ!$A$4:$A$13,0)) | K16: 鉄・ニッケル
A17: 13 | B17: B5 | C17: ヒギエア | D17: 小惑星 | E17: 330000000 | F17: 7.4 | G17: =パラメータ!$B$3*パラメータ!$B$4^A17 | H17: =F17-F16 | I17: =ROUND(パラメータ!$B$5*G16*H17*パラメータ!$B$7*パラメータ!$B$6,-2) | J17: =E17/INDEX(速度カーブ!$D$4:$D$13,MATCH(B17,速度カーブ!$A$4:$A$13,0)) | K17: 炭素質・水氷
A18: 14 | B18: B5 | C18: ルテティア | D18: 小惑星 | E18: 350000000 | F18: 8.2 | G18: =パラメータ!$B$3*パラメータ!$B$4^A18 | H18: =F18-F17 | I18: =ROUND(パラメータ!$B$5*G17*H18*パラメータ!$B$7*パラメータ!$B$6,-2) | J18: =E18/INDEX(速度カーブ!$D$4:$D$13,MATCH(B18,速度カーブ!$A$4:$A$13,0)) | K18: 鉄・ニッケル・タングステン・モリブデン(推定)
A19: 15 | B19: B5 | C19: プシケ | D19: 小惑星 | E19: 370000000 | F19: 9 | G19: =パラメータ!$B$3*パラメータ!$B$4^A19 | H19: =F19-F18 | I19: =ROUND(パラメータ!$B$5*G18*H19*パラメータ!$B$7*パラメータ!$B$6,-2) | J19: =E19/INDEX(速度カーブ!$D$4:$D$13,MATCH(B19,速度カーブ!$A$4:$A$13,0)) | K19: 鉄・ニッケル・コバルト・白金・パラジウム・金(推定) | L19: バンド最後の金属天体
A20: 16 | B20: B6 | C20: 木星 | D20: 惑星 | E20: 630000000 | F20: 10 | G20: =パラメータ!$B$3*パラメータ!$B$4^A20 | H20: =F20-F19 | I20: =ROUND(パラメータ!$B$5*G19*H20*パラメータ!$B$7*パラメータ!$B$6,-2) | J20: =E20/INDEX(速度カーブ!$D$4:$D$13,MATCH(B20,速度カーブ!$A$4:$A$13,0)) | K20: 水素・ヘリウム(大気) | L20: 着陸不可・大気採取
A21: 17 | B21: B6 | C21: イオ | D21: 衛星 | E21: 631000000 | F21: 11 | G21: =パラメータ!$B$3*パラメータ!$B$4^A21 | H21: =F21-F20 | I21: =ROUND(パラメータ!$B$5*G20*H21*パラメータ!$B$7*パラメータ!$B$6,-2) | J21: =E21/INDEX(速度カーブ!$D$4:$D$13,MATCH(B21,速度カーブ!$A$4:$A$13,0)) | K21: 硫黄
A22: 18 | B22: B6 | C22: エウロパ | D22: 衛星 | E22: 632000000 | F22: 12 | G22: =パラメータ!$B$3*パラメータ!$B$4^A22 | H22: =F22-F21 | I22: =ROUND(パラメータ!$B$5*G21*H22*パラメータ!$B$7*パラメータ!$B$6,-2) | J22: =E22/INDEX(速度カーブ!$D$4:$D$13,MATCH(B22,速度カーブ!$A$4:$A$13,0)) | K22: 水氷
A23: 19 | B23: B6 | C23: ガニメデ | D23: 衛星 | E23: 633000000 | F23: 13 | G23: =パラメータ!$B$3*パラメータ!$B$4^A23 | H23: =F23-F22 | I23: =ROUND(パラメータ!$B$5*G22*H23*パラメータ!$B$7*パラメータ!$B$6,-2) | J23: =E23/INDEX(速度カーブ!$D$4:$D$13,MATCH(B23,速度カーブ!$A$4:$A$13,0)) | K23: 水氷・鉄
A24: 20 | B24: B6 | C24: カリスト | D24: 衛星 | E24: 634000000 | F24: 14 | G24: =パラメータ!$B$3*パラメータ!$B$4^A24 | H24: =F24-F23 | I24: =ROUND(パラメータ!$B$5*G23*H24*パラメータ!$B$7*パラメータ!$B$6,-2) | J24: =E24/INDEX(速度カーブ!$D$4:$D$13,MATCH(B24,速度カーブ!$A$4:$A$13,0)) | K24: 水氷
A25: 21 | B25: B7 | C25: 土星 | D25: 惑星 | E25: 1280000000 | F25: 15 | G25: =パラメータ!$B$3*パラメータ!$B$4^A25 | H25: =F25-F24 | I25: =ROUND(パラメータ!$B$5*G24*H25*パラメータ!$B$7*パラメータ!$B$6,-2) | J25: =E25/INDEX(速度カーブ!$D$4:$D$13,MATCH(B25,速度カーブ!$A$4:$A$13,0)) | K25: 水素・ヘリウム(大気) | L25: 着陸不可・大気採取
A26: 22 | B26: B7 | C26: ミマス | D26: 衛星 | E26: 1281000000 | F26: 16.2 | G26: =パラメータ!$B$3*パラメータ!$B$4^A26 | H26: =F26-F25 | I26: =ROUND(パラメータ!$B$5*G25*H26*パラメータ!$B$7*パラメータ!$B$6,-2) | J26: =E26/INDEX(速度カーブ!$D$4:$D$13,MATCH(B26,速度カーブ!$A$4:$A$13,0)) | K26: 氷
A27: 23 | B27: B7 | C27: エンケラドス | D27: 衛星 | E27: 1282000000 | F27: 17.4 | G27: =パラメータ!$B$3*パラメータ!$B$4^A27 | H27: =F27-F26 | I27: =ROUND(パラメータ!$B$5*G26*H27*パラメータ!$B$7*パラメータ!$B$6,-2) | J27: =E27/INDEX(速度カーブ!$D$4:$D$13,MATCH(B27,速度カーブ!$A$4:$A$13,0)) | K27: 水
A28: 24 | B28: B7 | C28: テティス | D28: 衛星 | E28: 1283000000 | F28: 18.6 | G28: =パラメータ!$B$3*パラメータ!$B$4^A28 | H28: =F28-F27 | I28: =ROUND(パラメータ!$B$5*G27*H28*パラメータ!$B$7*パラメータ!$B$6,-2) | J28: =E28/INDEX(速度カーブ!$D$4:$D$13,MATCH(B28,速度カーブ!$A$4:$A$13,0)) | K28: 氷
A29: 25 | B29: B7 | C29: ディオネ | D29: 衛星 | E29: 1284000000 | F29: 19.8 | G29: =パラメータ!$B$3*パラメータ!$B$4^A29 | H29: =F29-F28 | I29: =ROUND(パラメータ!$B$5*G28*H29*パラメータ!$B$7*パラメータ!$B$6,-2) | J29: =E29/INDEX(速度カーブ!$D$4:$D$13,MATCH(B29,速度カーブ!$A$4:$A$13,0)) | K29: 氷
A30: 26 | B30: B7 | C30: レア | D30: 衛星 | E30: 1285000000 | F30: 21 | G30: =パラメータ!$B$3*パラメータ!$B$4^A30 | H30: =F30-F29 | I30: =ROUND(パラメータ!$B$5*G29*H30*パラメータ!$B$7*パラメータ!$B$6,-2) | J30: =E30/INDEX(速度カーブ!$D$4:$D$13,MATCH(B30,速度カーブ!$A$4:$A$13,0)) | K30: 氷
A31: 27 | B31: B7 | C31: タイタン | D31: 衛星 | E31: 1286000000 | F31: 22.5 | G31: =パラメータ!$B$3*パラメータ!$B$4^A31 | H31: =F31-F30 | I31: =ROUND(パラメータ!$B$5*G30*H31*パラメータ!$B$7*パラメータ!$B$6,-2) | J31: =E31/INDEX(速度カーブ!$D$4:$D$13,MATCH(B31,速度カーブ!$A$4:$A$13,0)) | K31: メタン・炭化水素(液体炭化水素湖=実在)
A32: 28 | B32: B7 | C32: イアペトゥス | D32: 衛星 | E32: 1287000000 | F32: 24 | G32: =パラメータ!$B$3*パラメータ!$B$4^A32 | H32: =F32-F31 | I32: =ROUND(パラメータ!$B$5*G31*H32*パラメータ!$B$7*パラメータ!$B$6,-2) | J32: =E32/INDEX(速度カーブ!$D$4:$D$13,MATCH(B32,速度カーブ!$A$4:$A$13,0)) | K32: 氷・炭素質
A33: 29 | B33: B8 | C33: 天王星 | D33: 惑星 | E33: 2700000000 | F33: 25.5 | G33: =パラメータ!$B$3*パラメータ!$B$4^A33 | H33: =F33-F32 | I33: =ROUND(パラメータ!$B$5*G32*H33*パラメータ!$B$7*パラメータ!$B$6,-2) | J33: =E33/INDEX(速度カーブ!$D$4:$D$13,MATCH(B33,速度カーブ!$A$4:$A$13,0)) | K33: メタン・アンモニア(大気) | L33: 着陸不可・大気採取
A34: 30 | B34: B8 | C34: ミランダ | D34: 衛星 | E34: 2701000000 | F34: 27 | G34: =パラメータ!$B$3*パラメータ!$B$4^A34 | H34: =F34-F33 | I34: =ROUND(パラメータ!$B$5*G33*H34*パラメータ!$B$7*パラメータ!$B$6,-2) | J34: =E34/INDEX(速度カーブ!$D$4:$D$13,MATCH(B34,速度カーブ!$A$4:$A$13,0)) | K34: 氷
A35: 31 | B35: B8 | C35: アリエル | D35: 衛星 | E35: 2702000000 | F35: 28.5 | G35: =パラメータ!$B$3*パラメータ!$B$4^A35 | H35: =F35-F34 | I35: =ROUND(パラメータ!$B$5*G34*H35*パラメータ!$B$7*パラメータ!$B$6,-2) | J35: =E35/INDEX(速度カーブ!$D$4:$D$13,MATCH(B35,速度カーブ!$A$4:$A$13,0)) | K35: 氷
A36: 32 | B36: B8 | C36: ウンブリエル | D36: 衛星 | E36: 2703000000 | F36: 30 | G36: =パラメータ!$B$3*パラメータ!$B$4^A36 | H36: =F36-F35 | I36: =ROUND(パラメータ!$B$5*G35*H36*パラメータ!$B$7*パラメータ!$B$6,-2) | J36: =E36/INDEX(速度カーブ!$D$4:$D$13,MATCH(B36,速度カーブ!$A$4:$A$13,0)) | K36: 氷
A37: 33 | B37: B8 | C37: チタニア | D37: 衛星 | E37: 2704000000 | F37: 32 | G37: =パラメータ!$B$3*パラメータ!$B$4^A37 | H37: =F37-F36 | I37: =ROUND(パラメータ!$B$5*G36*H37*パラメータ!$B$7*パラメータ!$B$6,-2) | J37: =E37/INDEX(速度カーブ!$D$4:$D$13,MATCH(B37,速度カーブ!$A$4:$A$13,0)) | K37: 氷
A38: 34 | B38: B8 | C38: オベロン | D38: 衛星 | E38: 2705000000 | F38: 34 | G38: =パラメータ!$B$3*パラメータ!$B$4^A38 | H38: =F38-F37 | I38: =ROUND(パラメータ!$B$5*G37*H38*パラメータ!$B$7*パラメータ!$B$6,-2) | J38: =E38/INDEX(速度カーブ!$D$4:$D$13,MATCH(B38,速度カーブ!$A$4:$A$13,0)) | K38: 氷
A39: 35 | B39: B9 | C39: 海王星 | D39: 惑星 | E39: 4350000000 | F39: 36 | G39: =パラメータ!$B$3*パラメータ!$B$4^A39 | H39: =F39-F38 | I39: =ROUND(パラメータ!$B$5*G38*H39*パラメータ!$B$7*パラメータ!$B$6,-2) | J39: =E39/INDEX(速度カーブ!$D$4:$D$13,MATCH(B39,速度カーブ!$A$4:$A$13,0)) | K39: メタン(大気) | L39: 着陸不可・大気採取
A40: 36 | B40: B9 | C40: プロテウス | D40: 衛星 | E40: 4351000000 | F40: 38 | G40: =パラメータ!$B$3*パラメータ!$B$4^A40 | H40: =F40-F39 | I40: =ROUND(パラメータ!$B$5*G39*H40*パラメータ!$B$7*パラメータ!$B$6,-2) | J40: =E40/INDEX(速度カーブ!$D$4:$D$13,MATCH(B40,速度カーブ!$A$4:$A$13,0)) | K40: 氷
A41: 37 | B41: B9 | C41: トリトン | D41: 衛星 | E41: 4352000000 | F41: 40 | G41: =パラメータ!$B$3*パラメータ!$B$4^A41 | H41: =F41-F40 | I41: =ROUND(パラメータ!$B$5*G40*H41*パラメータ!$B$7*パラメータ!$B$6,-2) | J41: =E41/INDEX(速度カーブ!$D$4:$D$13,MATCH(B41,速度カーブ!$A$4:$A$13,0)) | K41: 窒素氷・メタン氷
...

Sheet 精錬・加工
A1: 精錬・加工(Smelt & Craft)― 加工品価格は成分の当日市況から自動計算(市況連動が加工品まで波及)
A3: 【二層価格ルール】
A4: 1. 採掘物は「鉱石」:鉱石の売却単価 = 対応金属の当日価格 × 品位係数(天体ごと・下記パラメータ)。そのまま売れば安いが即時
A5: 2. 精錬所(ステーション)で精錬すると「金属」になり、当日のLME/スポット価格そのままで売却できる(回収率を乗算)
A6: 3. さらに加工(合金・材料)すると付加価値が乗る。加工品価格 = Σ(成分量×当日成分価格) × 加工プレミアム → 成分市況に自動連動
A7: 4. 精錬・加工は時間がかかる(キュー式・放置で進行)。「すぐ売る」vs「時間をかけて高く売る」のトレードオフ
A10: 【精錬パラメータ(青字=調整用)】
A11: 鉱石の品位係数(標準) | B11: 0.35 | C11: 鉱石売値=金属価格×0.35。天体により0.2〜0.5
A12: 精錬回収率(Lv1) | B12: 0.7 | C12: 強化で最大0.95。精錬売値=金属価格×回収率
A13: 精錬処理能力 Lv1(kg/時) | B13: 500 | C13: 強化+25%/Lv・マイルストーン×2
A16: 【加工レシピ】成分単価は資源マスタの当日価格に自動連動。実勢参考価格に合うよう加工プレミアム(青字)を調整済み
A17: 加工品 | B17: レシピ(1kgあたり成分) | C17: 成分コスト(NOVA/kg) | D17: 加工プレミアム | E17: 販売単価(NOVA/kg) | F17: 実勢参考 | G17: 金型メモ
A18: 鋼(スチール) | B18: 鉄1.0+石炭0.5(コークス) | C18: =資源マスタ!$D$4*1+資源マスタ!$D$5*0.5 | D18: 5 | E18: =C18*D18 | F18: 熱延コイル 約$0.85/kg | G18: SS400・S45C等の母材。製鉄に石炭=地球の石炭に用途
A19: ステンレス鋼 | B19: 鋼0.72+クロム0.18+ニッケル0.10 | C19: =C18*0.72+資源マスタ!$D$11*0.18+資源マスタ!$D$15*0.1 | D19: 1.1 | E19: =C19*D19 | F19: SUS304 約$3/kg
A20: 合金工具鋼(ダイス鋼) | B20: 鋼0.85+クロム0.12+モリブデン0.01+バナジウム0.005 | C20: =C18*0.85+資源マスタ!$D$11*0.12+資源マスタ!$D$19*0.01+資源マスタ!$D$16*0.005 | D20: 5.5 | E20: =C20*D20 | F20: SKD11相当 約$10/kg | G20: ★SKD11の組成そのもの(13%Cr系)
A21: 高速度鋼(ハイス) | B21: 鋼0.8+W0.06+Mo0.05+Cr0.04+V0.02+Co0.05 | C21: =C18*0.8+資源マスタ!$D$20*0.06+資源マスタ!$D$19*0.05+資源マスタ!$D$11*0.04+資源マスタ!$D$16*0.02+資源マスタ!$D$17*0.05 | D21: 1.8 | E21: =C21*D21 | F21: SKH51相当 約$30/kg | G21: ★SKH51の組成そのもの
A22: 超硬合金 | B22: タングステン0.85+コバルト0.10+炭素0.05 | C22: =資源マスタ!$D$20*0.85+資源マスタ!$D$17*0.1+資源マスタ!$D$5*0.05 | D22: 1.5 | E22: =C22*D22 | F22: 超硬素材 $200〜300/kg | G22: ★WC+Co。タングステン高騰が超硬価格に直結する現実の構図が数式に
A23: 青銅 | B23: 銅0.88+錫0.12 | C23: =資源マスタ!$D$14*0.88+資源マスタ!$D$18*0.12 | D23: 1.2 | E23: =C23*D23 | F23: 砲金系 約$15/kg
A26: 加工品の用途:①高値売却 ②船・設備の建造/強化素材(例:船体強化=チタン合金、金型研究=ダイス鋼) ③納品契約の対象
A27: 教育効果:社員がゲーム内で超硬(W+Co)やダイス鋼(鋼+Cr+Mo+V)を合成する=金型材の組成を体で覚える
A28: 実装フェーズ(決定):精錬(鉱石→金属)はMVPから実装。MVP対象=鉄・ニッケル・チタンの3種。合金加工はv1.1で追加
A30: 鉄の精錬(MVP):鉄鉱石(指数$105/t)→銑鉄(参考$420/t≒11,046 NOVA/kg)×回収率。鉄だけは鉱石指数と銑鉄価格が両方実在=二層価格の教材(チュートリアルで使用)

Sheet 速度カーブ
A1: 全船統一速度カーブ(バンド到達時の航行研究レベルで決まる共通速度)
A3: バンド | B3: 代表距離(km・バンド最遠) | C3: 目標片道時間(分) | D3: 必要速度S(km/分) | E3: 対前バンド比 | F3: 到達目安(日)
A4: B1 | B4: 380000 | C4: 1 | D4: =B4/C4 | E4: 基準 | F4: 0
A5: B2 | B5: 25000000 | C5: 5 | D5: =B5/C5 | E5: =D5/D4 | F5: 0.2
A6: B3 | B6: 77000000 | C6: 10 | D6: =B6/C6 | E6: =D6/D5 | F6: 2
A7: B4 | B7: 78200000 | C7: 10 | D7: =B7/C7 | E7: =D7/D6 | F7: 3
A8: B5 | B8: 370000000 | C8: 12 | D8: =B8/C8 | E8: =D8/D7 | F8: 5
A9: B6 | B9: 634000000 | C9: 13 | D9: =B9/C9 | E9: =D9/D8 | F9: 10
A10: B7 | B10: 1287000000 | C10: 20 | D10: =B10/C10 | E10: =D10/D9 | F10: 15
A11: B8 | B11: 2705000000 | C11: 30 | D11: =B11/C11 | E11: =D11/D10 | F11: 25.5
A12: B9 | B12: 4353000000 | C12: 45 | D12: =B12/C12 | E12: =D12/D11 | F12: 36
A13: B10 | B13: 13000000000 | C13: 120 | D13: =B13/C13 | E13: =D13/D12 | F13: 44
A15: 速度は全船共通・船種差なし(高速船は廃止)。B1→B2の×13は「惑星間航行エンジン解禁」演出。
A16: 終盤(B7以降)は意図的に速度成長を鈍らせ、最前線の片道を20分→30分→45分→セドナ約2時間へ段階的に延ばす。外縁便は「就寝前に出す」遊び。
A17: 青字の目標片道時間を変えると、必要速度と天体マスタの全片道時間が連動して再計算される。対前バンド比が1.0未満にならないよう注意(速度は単調増加)。

Sheet 船・輸送設計
A1: 船・積載・輸送の数値設計 ― 持ち帰り換金モデル(収入=着艦時に当日市況で売却)
A3: 1. 収入イベントは着艦時のみ。船は「飛ぶ→掘る→満杯→帰る→売る→再出発」を自動ループ(操作は方針決めだけ)
A4: 2. 資源の2階級制:収入資源(高単価・軽量=金属・貴金属・He3・ウラン・希少物質)/素材資源(バルク=水・氷・メタン等。研究・建造・契約用で売り物ではない)
A5: 3. 輸送船=採掘船を常駐させて自分がピストンする増強手段。現地ストレージ満杯=搬出不足のサイン→採掘停止
A6: 4. 外縁バンドの収入アンカーはHe3(現実の採取構想でも天王星・海王星が本命=科学的裏付けあり)
A9: 【船パラメータ(Lv1基準・青字=調整用)】
A10: 採掘船:採掘レート基準(kg/秒) | B10: 3 | C10: 強化+12%/Lv・マイルストーン×2(Lv10/25/50)
A11: 採掘船:積載量(kg) | B11: 180 | C11: 強化+25%/Lv・マイルストーン×2
A12: 輸送船:積載量(kg) | B12: 500 | C12: 強化+30%/Lv・マイルストーン×2
A13: 積込+荷降ろし(秒/往復) | B13: 120 | C13: 自動化Lvで短縮
A14: 船の建造コスト(現フロンティア収入の秒数分) | B14: 1800 | C14: 建造コスト = v_frontier × 1,800
A17: 【1便あたりの経済(採掘船単独ループの検算)】周期=片道×2+採掘時間(積載÷M)+積込。収入レート=積載×P̄÷周期
A18: 天体 | B18: 目標v(NOVA/s) | C18: 収入資源P̄(NOVA/kg) | D18: 積載C(kg) | E18: 採掘M(kg/s) | F18: 片道(分) | G18: 周期(秒) | H18: 1便の売上(NOVA) | I18: 実収入(NOVA/s) | J18: 対目標
A19: 月(鉄・チタン) | B19: 2762 | C19: 4200 | D19: 180 | E19: 3 | F19: 1 | G19: =F19*2*60+D19/E19+$B$13 | H19: =D19*C19 | I19: =H19/G19 | J19: =I19/B19
A20: 火星(鉄) | B20: 19282 | C20: 2762 | D20: 1500 | E20: 12 | F20: 10 | G20: =F20*2*60+D20/E20+$B$13 | H20: =D20*C20 | I20: =H20/G20 | J20: =I20/B20
A21: プシケ(貴金属混合) | B21: 177878 | C21: 250000 | D21: 900 | E21: 1.2 | F21: 6.9 | G21: =F21*2*60+D21/E21+$B$13 | H21: =D21*C21 | I21: =H21/G21 | J21: =I21/B21
A22: 土星圏(He3・タイタン炭化水素) | B22: 940151 | C22: 2500000 | D22: 600 | E22: 0.5 | F22: 20 | G22: =F22*2*60+D22/E22+$B$13 | H22: =D22*C22 | I22: =H22/G22 | J22: =I22/B22
A23: 海王星(He3) | B23: 105427627 | C23: 100000000000 | D23: 2 | E23: 0.001 | F23: 45 | G23: =F23*2*60+D23/E23+$B$13 | H23: =D23*C23 | I23: =H23/G23 | J23: =I23/B23
A24: セドナ(希少物質) | B24: 2234949306 | C24: 500000000000 | D24: 40 | E24: 0.004 | F24: 120 | G24: =F24*2*60+D24/E24+$B$13 | H24: =D24*C24 | I24: =H24/G24 | J24: =I24/B24
A26: 対目標が100%前後になるようP̄(収入資源の配合)・積載C・採掘Mを各天体で調整する。輸送船ペア(採掘船常駐+ピストン)なら採掘時間が周期から消え、実収入が上振れする。
A27: 素材資源(バルク)はこの表に含めない(収入計算外)。素材の需要量は研究・建造の要求と納品契約で設計する。

Sheet 強化コスト曲線
A1: 採掘速度アップグレードの汎用曲線(1天体分の例)
A3: C0:Lv1コスト(例=対象天体アンロック価格の10%、VND桁) | B3: 27600000
A4: コスト成長率(Lvごと) | B4: 1.55
A5: 効果成長率(Lvごと) | B5: 1.12
A6: マイルストーン倍率(Lv10/25/50到達時) | B6: 2
A8: Lv | B8: コスト(cr) | C8: 累積コスト(cr) | D8: 効果倍率(×)
A9: 1 | B9: =$B$3*$B$4^(A9-1) | C9: =B9 | D9: =$B$5^(A9-1)*IF(A9>=10,$B$6,1)*IF(A9>=25,$B$6,1)*IF(A9>=50,$B$6,1)
A10: 2 | B10: =$B$3*$B$4^(A10-1) | C10: =C9+B10 | D10: =$B$5^(A10-1)*IF(A10>=10,$B$6,1)*IF(A10>=25,$B$6,1)*IF(A10>=50,$B$6,1)
A11: 3 | B11: =$B$3*$B$4^(A11-1) | C11: =C10+B11 | D11: =$B$5^(A11-1)*IF(A11>=10,$B$6,1)*IF(A11>=25,$B$6,1)*IF(A11>=50,$B$6,1)
A12: 4 | B12: =$B$3*$B$4^(A12-1) | C12: =C11+B12 | D12: =$B$5^(A12-1)*IF(A12>=10,$B$6,1)*IF(A12>=25,$B$6,1)*IF(A12>=50,$B$6,1)
A13: 5 | B13: =$B$3*$B$4^(A13-1) | C13: =C12+B13 | D13: =$B$5^(A13-1)*IF(A13>=10,$B$6,1)*IF(A13>=25,$B$6,1)*IF(A13>=50,$B$6,1)
A14: 6 | B14: =$B$3*$B$4^(A14-1) | C14: =C13+B14 | D14: =$B$5^(A14-1)*IF(A14>=10,$B$6,1)*IF(A14>=25,$B$6,1)*IF(A14>=50,$B$6,1)
A15: 7 | B15: =$B$3*$B$4^(A15-1) | C15: =C14+B15 | D15: =$B$5^(A15-1)*IF(A15>=10,$B$6,1)*IF(A15>=25,$B$6,1)*IF(A15>=50,$B$6,1)
A16: 8 | B16: =$B$3*$B$4^(A16-1) | C16: =C15+B16 | D16: =$B$5^(A16-1)*IF(A16>=10,$B$6,1)*IF(A16>=25,$B$6,1)*IF(A16>=50,$B$6,1)
A17: 9 | B17: =$B$3*$B$4^(A17-1) | C17: =C16+B17 | D17: =$B$5^(A17-1)*IF(A17>=10,$B$6,1)*IF(A17>=25,$B$6,1)*IF(A17>=50,$B$6,1)
A18: 10 | B18: =$B$3*$B$4^(A18-1) | C18: =C17+B18 | D18: =$B$5^(A18-1)*IF(A18>=10,$B$6,1)*IF(A18>=25,$B$6,1)*IF(A18>=50,$B$6,1)
A19: 11 | B19: =$B$3*$B$4^(A19-1) | C19: =C18+B19 | D19: =$B$5^(A19-1)*IF(A19>=10,$B$6,1)*IF(A19>=25,$B$6,1)*IF(A19>=50,$B$6,1)
A20: 12 | B20: =$B$3*$B$4^(A20-1) | C20: =C19+B20 | D20: =$B$5^(A20-1)*IF(A20>=10,$B$6,1)*IF(A20>=25,$B$6,1)*IF(A20>=50,$B$6,1)
A21: 13 | B21: =$B$3*$B$4^(A21-1) | C21: =C20+B21 | D21: =$B$5^(A21-1)*IF(A21>=10,$B$6,1)*IF(A21>=25,$B$6,1)*IF(A21>=50,$B$6,1)
... A58: 50 | B58: =$B$3*$B$4^(A58-1) | C58: =C57+B58 | D58: =$B$5^(A58-1)*IF(A58>=10,$B$6,1)*IF(A58>=25,$B$6,1)*IF(A58>=50,$B$6,1)
A60: 適用対象:採掘速度・積載量・移動速度など全強化に同型の曲線を使い、C0と成長率のみ項目別に変える。

Sheet 進行シミュレーション
A1: 日次シミュレーション(0〜90日)- パラメータと天体マスタから自動計算
A3: 日 | B3: 開放済み天体数 | C3: 収入レート(cr/秒) | D3: 日次獲得(cr) | E3: 累積獲得(cr) | F3: 累積アンロック費(cr) | G3: アンロック充足率
A4: 0 | B4: =COUNTIF(天体マスタ!$F$4:$F$53,"<="&A4) | C4: =パラメータ!$B$5*パラメータ!$B$3*パラメータ!$B$4^(B4-1) | D4: =C4*パラメータ!$B$7 | E4: =D4 | F4: =SUMIF(天体マスタ!$F$4:$F$53,"<="&A4,天体マスタ!$I$4:$I$53) | G4: =IF(F4=0,"-",E4*パラメータ!$B$6/F4)
A5: 1 | B5: =COUNTIF(天体マスタ!$F$4:$F$53,"<="&A5) | C5: =パラメータ!$B$5*パラメータ!$B$3*パラメータ!$B$4^(B5-1) | D5: =C5*パラメータ!$B$7 | E5: =E4+D5 | F5: =SUMIF(天体マスタ!$F$4:$F$53,"<="&A5,天体マスタ!$I$4:$I$53) | G5: =IF(F5=0,"-",E5*パラメータ!$B$6/F5)
A6: 2 | B6: =COUNTIF(天体マスタ!$F$4:$F$53,"<="&A6) | C6: =パラメータ!$B$5*パラメータ!$B$3*パラメータ!$B$4^(B6-1) | D6: =C6*パラメータ!$B$7 | E6: =E5+D6 | F6: =SUMIF(天体マスタ!$F$4:$F$53,"<="&A6,天体マスタ!$I$4:$I$53) | G6: =IF(F6=0,"-",E6*パラメータ!$B$6/F6)
A7: 3 | B7: =COUNTIF(天体マスタ!$F$4:$F$53,"<="&A7) | C7: =パラメータ!$B$5*パラメータ!$B$3*パラメータ!$B$4^(B7-1) | D7: =C7*パラメータ!$B$7 | E7: =E6+D7 | F7: =SUMIF(天体マスタ!$F$4:$F$53,"<="&A7,天体マスタ!$I$4:$I$53) | G7: =IF(F7=0,"-",E7*パラメータ!$B$6/F7)
A8: 4 | B8: =COUNTIF(天体マスタ!$F$4:$F$53,"<="&A8) | C8: =パラメータ!$B$5*パラメータ!$B$3*パラメータ!$B$4^(B8-1) | D8: =C8*パラメータ!$B$7 | E8: =E7+D8 | F8: =SUMIF(天体マスタ!$F$4:$F$53,"<="&A8,天体マスタ!$I$4:$I$53) | G8: =IF(F8=0,"-",E8*パラメータ!$B$6/F8)
A9: 5 | B9: =COUNTIF(天体マスタ!$F$4:$F$53,"<="&A9) | C9: =パラメータ!$B$5*パラメータ!$B$3*パラメータ!$B$4^(B9-1) | D9: =C9*パラメータ!$B$7 | E9: =E8+D9 | F9: =SUMIF(天体マスタ!$F$4:$F$53,"<="&A9,天体マスタ!$I$4:$I$53) | G9: =IF(F9=0,"-",E9*パラメータ!$B$6/F9)
A10: 6 | B10: =COUNTIF(天体マスタ!$F$4:$F$53,"<="&A10) | C10: =パラメータ!$B$5*パラメータ!$B$3*パラメータ!$B$4^(B10-1) | D10: =C10*パラメータ!$B$7 | E10: =E9+D10 | F10: =SUMIF(天体マスタ!$F$4:$F$53,"<="&A10,天体マスタ!$I$4:$I$53) | G10: =IF(F10=0,"-",E10*パラメータ!$B$6/F10)
A11: 7 | B11: =COUNTIF(天体マスタ!$F$4:$F$53,"<="&A11) | C11: =パラメータ!$B$5*パラメータ!$B$3*パラメータ!$B$4^(B11-1) | D11: =C11*パラメータ!$B$7 | E11: =E10+D11 | F11: =SUMIF(天体マスタ!$F$4:$F$53,"<="&A11,天体マスタ!$I$4:$I$53) | G11: =IF(F11=0,"-",E11*パラメータ!$B$6/F11)
A12: 8 | B12: =COUNTIF(天体マスタ!$F$4:$F$53,"<="&A12) | C12: =パラメータ!$B$5*パラメータ!$B$3*パラメータ!$B$4^(B12-1) | D12: =C12*パラメータ!$B$7 | E12: =E11+D12 | F12: =SUMIF(天体マスタ!$F$4:$F$53,"<="&A12,天体マスタ!$I$4:$I$53) | G12: =IF(F12=0,"-",E12*パラメータ!$B$6/F12)
A13: 9 | B13: =COUNTIF(天体マスタ!$F$4:$F$53,"<="&A13) | C13: =パラメータ!$B$5*パラメータ!$B$3*パラメータ!$B$4^(B13-1) | D13: =C13*パラメータ!$B$7 | E13: =E12+D13 | F13: =SUMIF(天体マスタ!$F$4:$F$53,"<="&A13,天体マスタ!$I$4:$I$53) | G13: =IF(F13=0,"-",E13*パラメータ!$B$6/F13)
A14: 10 | B14: =COUNTIF(天体マスタ!$F$4:$F$53,"<="&A14) | C14: =パラメータ!$B$5*パラメータ!$B$3*パラメータ!$B$4^(B14-1) | D14: =C14*パラメータ!$B$7 | E14: =E13+D14 | F14: =SUMIF(天体マスタ!$F$4:$F$53,"<="&A14,天体マスタ!$I$4:$I$53) | G14: =IF(F14=0,"-",E14*パラメータ!$B$6/F14)
A15: 11 | B15: =COUNTIF(天体マスタ!$F$4:$F$53,"<="&A15) | C15: =パラメータ!$B$5*パラメータ!$B$3*パラメータ!$B$4^(B15-1) | D15: =C15*パラメータ!$B$7 | E15: =E14+D15 | F15: =SUMIF(天体マスタ!$F$4:$F$53,"<="&A15,天体マスタ!$I$4:$I$53) | G15: =IF(F15=0,"-",E15*パラメータ!$B$6/F15)
A16: 12 | B16: =COUNTIF(天体マスタ!$F$4:$F$53,"<="&A16) | C16: =パラメータ!$B$5*パラメータ!$B$3*パラメータ!$B$4^(B16-1) | D16: =C16*パラメータ!$B$7 | E16: =E15+D16 | F16: =SUMIF(天体マスタ!$F$4:$F$53,"<="&A16,天体マスタ!$I$4:$I$53) | G16: =IF(F16=0,"-",E16*パラメータ!$B$6/F16)
... A94: 90 | B94: =COUNTIF(天体マスタ!$F$4:$F$53,"<="&A94) | C94: =パラメータ!$B$5*パラメータ!$B$3*パラメータ!$B$4^(B94-1) | D94: =C94*パラメータ!$B$7 | E94: =E93+D94 | F94: =SUMIF(天体マスタ!$F$4:$F$53,"<="&A94,天体マスタ!$I$4:$I$53) | G94: =IF(F94=0,"-",E94*パラメータ!$B$6/F94)
A96: 充足率が100%前後で推移していれば、目標日どおりのペースで開放費を賄える設計になっている(強化費は残り s 以外の収入で賄う想定)。
